Workbook

Sheet REPORT | RECAP
B2: INSTALLATION SUMMARY REPORT
B3: As of 29/02/2024
B4: NO | C4: MUNICIPALITY | D4: BARANGAYS | G4: LOS | K4: INSTALLATIONS1 | R4: BRGY
G5: YES | H5: NO | K5: BAP | L5: ELS | M5: NHS | N5: SHS | O5: REL | P5: CKP | Q5: ETC | R5: WIN
B6: {=INSTALLATION!A47:Q47} -> 1 | C6: AURORA | D6: 44 | E6: BARANGAYS | F6: LOS | NLOS | G6: 37 | H6: 7 | I6: INSTALLATIONS | J6: 0 | K6: 25 | L6: 2 | M6: 2 | N6: 0 | O6: 3 | P6: 1 | Q6: 0 | R6: 25
B7: {=INSTALLATION!A76:Q76} -> 2 | C7: BAYOG | D7: 28 | E7: BARANGAYS | F7: LOS | NLOS | G7: 0 | H7: 28 | I7: INSTALLATIONS | J7: 0 | K7: 0 | L7: 0 | M7: 0 | N7: 0 | O7: 0 | P7: 0 | Q7: 0 | R7: 0
B8: {=INSTALLATION!A101:Q101} -> 3 | C8: DIMATALING | D8: 24 | E8: BARANGAYS | F8: LOS | NLOS | G8: 23 | H8: 1 | I8: INSTALLATIONS | J8: 0 | K8: 12 | L8: 1 | M8: 1 | N8: 0 | O8: 3 | P8: 0 | Q8: 0 | R8: 12
B9: {=INSTALLATION!A132:Q132} -> 4 | C9: DINAS | D9: 30 | E9: BARANGAYS | F9: LOS | NLOS | G9: 28 | H9: 2 | I9: INSTALLATIONS | J9: 0 | K9: 19 | L9: 6 | M9: 7 | N9: 1 | O9: 1 | P9: 0 | Q9: 2 | R9: 19
B10: {=INSTALLATION!A163:Q163} -> 5 | C10: DUMALINAO | D10: 30 | E10: BARANGAYS | F10: LOS | NLOS | G10: 26 | H10: 4 | I10: INSTALLATIONS | J10: 0 | K10: 24 | L10: 7 | M10: 4 | N10: 1 | O10: 0 | P10: 0 | Q10: 2 | R10: 24
B11: {=INSTALLATION!A208:Q208} -> 6 | C11: DUMINGAG | D11: 44 | E11: BARANGAYS | F11: LOS | NLOS | G11: 32 | H11: 12 | I11: INSTALLATIONS | J11: 0 | K11: 15 | L11: 0 | M11: 0 | N11: 0 | O11: 0 | P11: 0 | Q11: 0 | R11: 15
B12: {=INSTALLATION!A226:Q226} -> 7 | C12: GUIPOS | D12: 17 | E12: BARANGAYS | F12: LOS | NLOS | G12: 13 | H12: 4 | I12: INSTALLATIONS | J12: 0 | K12: 12 | L12: 1 | M12: 3 | N12: 0 | O12: 2 | P12: 0 | Q12: 2 | R12: 13
B13: {=INSTALLATION!A241:Q241} -> 8 | C13: JOSEFINA | D13: 14 | E13: BARANGAYS | F13: LOS | NLOS | G13: 11 | H13: 3 | I13: INSTALLATIONS | J13: 0 | K13: 3 | L13: 0 | M13: 0 | N13: 0 | O13: 1 | P13: 1 | Q13: 0 | R13: 3
B14: {=INSTALLATION!A260:Q260} -> 9 | C14: KUMALARANG | D14: 18 | E14: BARANGAYS | F14: LOS | NLOS | G14: 10 | H14: 8 | I14: INSTALLATIONS | J14: 0 | K14: 6 | L14: 1 | M14: 0 | N14: 0 | O14: 3 | P14: 1 | Q14: 1 | R14: 8
B15: {=INSTALLATION!A286:Q286} -> 10 | C15: LABANGAN | D15: 25 | E15: BARANGAYS | F15: LOS | NLOS | G15: 21 | H15: 4 | I15: INSTALLATIONS | J15: 0 | K15: 20 | L15: 5 | M15: 0 | N15: 1 | O15: 1 | P15: 0 | Q15: 0 | R15: 20
B16: {=INSTALLATION!A301:Q301} -> 11 | C16: LAKEWOOD | D16: 14 | E16: BARANGAYS | F16: LOS | NLOS | G16: 4 | H16: 10 | I16: INSTALLATIONS | J16: 0 | K16: 1 | L16: 0 | M16: 1 | N16: 0 | O16: 1 | P16: 0 | Q16: 1 | R16: 2
B17: {=INSTALLATION!A328:Q328} -> 12 | C17: LAPUYAN | D17: 26 | E17: BARANGAYS | F17: LOS | NLOS | G17: 19 | H17: 7 | I17: INSTALLATIONS | J17: 0 | K17: 0 | L17: 1 | M17: 0 | N17: 0 | O17: 1 | P17: 0 | Q17: 0 | R17: 1
B18: {=INSTALLATION!A358:Q358} -> 13 | C18: MAHAYAG | D18: 29 | E18: BARANGAYS | F18: LOS | NLOS | G18: 25 | H18: 4 | I18: INSTALLATIONS | J18: 0 | K18: 14 | L18: 1 | M18: 0 | N18: 0 | O18: 1 | P18: 0 | Q18: 0 | R18: 15
B19: {=INSTALLATION!A376:Q376} -> 14 | C19: MARGOSATUBIG | D19: 17 | E19: BARANGAYS | F19: LOS | NLOS | G19: 13 | H19: 4 | I19: INSTALLATIONS | J19: 0 | K19: 4 | L19: 1 | M19: 0 | N19: 0 | O19: 1 | P19: 0 | Q19: 0 | R19: 4
B20: {=INSTALLATION!A410:Q410} -> 15 | C20: MIDSALIP | D20: 33 | E20: BARANGAYS | F20: LOS | NLOS | G20: 18 | H20: 15 | I20: INSTALLATIONS | J20: 0 | K20: 16 | L20: 1 | M20: 1 | N20: 0 | O20: 1 | P20: 0 | Q20: 1 | R20: 16
B21: {=INSTALLATION!A436:Q436} -> 16 | C21: MOLAVE | D21: 25 | E21: BARANGAYS | F21: LOS | NLOS | G21: 23 | H21: 2 | I21: INSTALLATIONS | J21: 0 | K21: 20 | L21: 2 | M21: 0 | N21: 1 | O21: 3 | P21: 0 | Q21: 1 | R21: 20
B22: {=INSTALLATION!A491:Q491} -> 17 | C22: PAGADIAN | D22: 54 | E22: BARANGAYS | F22: LOS | NLOS | G22: 51 | H22: 3 | I22: INSTALLATIONS | J22: 0 | K22: 49 | L22: 16 | M22: 7 | N22: 1 | O22: 10 | P22: 0 | Q22: 16 | R22: 50
B23: {=INSTALLATION!A507:Q507} -> 18 | C23: PITOGO | D23: 15 | E23: BARANGAYS | F23: LOS | NLOS | G23: 10 | H23: 5 | I23: INSTALLATIONS | J23: 0 | K23: 8 | L23: 2 | M23: 0 | N23: 0 | O23: 2 | P23: 0 | Q23: 1 | R23: 15
B24: {=INSTALLATION!A535:Q535} -> 19 | C24: RAMON MAGSAYSAY | D24: 27 | E24: BARANGAYS | F24: LOS | NLOS | G24: 25 | H24: 2 | I24: INSTALLATIONS | J24: 0 | K24: 18 | L24: 7 | M24: 1 | N24: 0 | O24: 0 | P24: 0 | Q24: 0 | R24: 19
B25: {=INSTALLATION!A554:Q554} -> 20 | C25: SAN MIGUEL | D25: 18 | E25: BARANGAYS | F25: LOS | NLOS | G25: 13 | H25: 5 | I25: INSTALLATIONS | J25: 0 | K25: 11 | L25: 5 | M25: 2 | N25: 0 | O25: 1 | P25: 0 | Q25: 1 | R25: 12
B26: {=INSTALLATION!A583:Q583} -> 21 | C26: SAN PABLO | D26: 28 | E26: BARANGAYS | F26: LOS | NLOS | G26: 17 | H26: 11 | I26: INSTALLATIONS | J26: 0 | K26: 14 | L26: 1 | M26: 0 | N26: 0 | O26: 1 | P26: 0 | Q26: 1 | R26: 14
B27: {=INSTALLATION!A602:Q602} -> 22 | C27: SOMINOT | D27: 18 | E27: BARANGAYS | F27: LOS | NLOS | G27: 16 | H27: 2 | I27: INSTALLATIONS | J27: 0 | K27: 9 | L27: 0 | M27: 0 | N27: 0 | O27: 0 | P27: 0 | Q27: 0 | R27: 9
B28: {=INSTALLATION!A618:Q618} -> 23 | C28: TABINA | D28: 15 | E28: BARANGAYS | F28: LOS | NLOS | G28: 11 | H28: 4 | I28: INSTALLATIONS | J28: 0 | K28: 9 | L28: 3 | M28: 1 | N28: 0 | O28: 5 | P28: 0 | Q28: 4 | R28: 9
B29: {=INSTALLATION!A650:Q650} -> 24 | C29: TAMBULIG | D29: 31 | E29: BARANGAYS | F29: LOS | NLOS | G29: 31 | H29: 0 | I29: INSTALLATIONS | J29: 0 | K29: 21 | L29: 5 | M29: 1 | N29: 0 | O29: 0 | P29: 1 | Q29: 0 | R29: 22
B30: {=INSTALLATION!A669:Q669} -> 25 | C30: TIGBAO | D30: 18 | E30: BARANGAYS | F30: LOS | NLOS | G30: 12 | H30: 6 | I30: INSTALLATIONS | J30: 0 | K30: 8 | L30: 1 | M30: 1 | N30: 0 | O30: 1 | P30: 0 | Q30: 1 | R30: 9
B31: {=INSTALLATION!A695:Q695} -> 26 | C31: TUKURAN | D31: 25 | E31: BARANGAYS | F31: LOS | NLOS | G31: 17 | H31: 8 | I31: INSTALLATIONS | J31: 0 | K31: 6 | L31: 3 | M31: 1 | N31: 0 | O31: 1 | P31: 1 | Q31: 1 | R31: 7
B32: {=INSTALLATION!A710:Q710} -> 27 | C32: VINCENZO SAGON | D32: 14 | E32: BARANGAYS | F32: LOS | NLOS | G32: 8 | H32: 6 | I32: INSTALLATIONS | J32: 0 | K32: 2 | L32: 0 | M32: 0 | N32: 0 | O32: 1 | P32: 0 | Q32: 0 | R32: 2
B33: =COUNTA(B6:B32) -> 27 | C33: TOTALS2 | D33: =SUM(D6:D32) -> 681 | E33: =SUM(E6:E32) -> 0 | F33: =SUM(F6:F32) -> 0 | G33: =SUM(G6:G32) -> 514 | H33: =SUM(H6:H32) -> 167 | K33: =SUM(K6:K32) -> 346 | L33: =SUM(L6:L32) -> 72 | M33: =SUM(M6:M32) -> 33 | N33: =SUM(N6:N32) -> 5 | O33: =SUM(O6:O32) -> 44 | P33: =SUM(P6:P32) -> 5 | Q33: =SUM(Q6:Q32) -> 35 | R33: =SUM(R6:R32) -> 365
B36: 1INSTS:
B38: WIN | C38: : Barangay with WiFi Installation(s) | G38: NHS | H38: : National High Schools (And or Integrated)
B39: LOS | C39: : Line of Sight (Between AP & Stations) | G39: SHS | H39: : Senior High School/Voc. Technical Schoool)
B40: BAP | C40: : Barangay Access Point (Halls, Centers) | G40: REL | H40: : Relay Stations (For priority remote barangay)
B41: ELS | C41: : Elementary Schools (And or Integrated) | G41: ETC | H41: : Other Installations (Purok, Gyms, Checkpoint)
B45: 2RECAP:
C46: Number of Barangays | D46: =D33 -> 681 | K46: Barangay Halls | O46: =K33 -> 346
C47: Barangays with clear-LOS | D47: =G33 -> 514 | K47: Total Public Schools | O47: =SUM(L33:N33) -> 110
...

Sheet INSTALLATION
A1: MUNICIPALITY | C1: BARANGAYS | F1: LINK INFORMATION | J1: INSTALLATIONS
A2: NO | B2: MUN NAME | C2: NO | D2: BRGY NAME | E2: COORDINATES | F2: LOS | H2: BASE STATION | I2: COORDINATES | J2: BAP | K2: ELS | L2: NHS | M2: SHS | N2: REL | O2: CKP | P2: ETC | Q2: MRK | R2: TOT
A3: 1 | B3: AURORA | C3: 1 | D3: Acad | E3: 7.9191, 123.6365 | F3: ✔️ | H3: Dipalutao BS | I3: 7.95464,123.4607 | J3: X | N3: X | Q3: =IF(COUNTA(J3:P3)=0,FALSE,TRUE) -> TRUE | R3: =COUNTA(J3:P3) -> 2
A4: 1 | B4: AURORA | C4: 2 | D4: Alang-Alang | E4: 7.9365, 123.5768 | F4: ✔️ | H4: San Jose BS | I4: 7.9556, 123.5828 | J4: X | Q4: =IF(COUNTA(J4:P4)=0,FALSE,TRUE) -> TRUE | R4: =COUNTA(J4:P4) -> 1
A5: 1 | B5: AURORA | C5: 3 | D5: Alegria | E5: 7.9443, 123.5537 | F5: ✔️ | H5: Dipalutao BS | I5: 7.95464,123.4607 | J5: X | Q5: =IF(COUNTA(J5:P5)=0,FALSE,TRUE) -> TRUE | R5: =COUNTA(J5:P5) -> 1
A6: 1 | B6: AURORA | C6: 4 | D6: Anonang | E6: 7.9407, 123.6245 | F6: ✔️ | H6: Dipalutao BS | I6: 7.95464,123.4607 | J6: X | N6: X | O6: X | Q6: =IF(COUNTA(J6:P6)=0,FALSE,TRUE) -> TRUE | R6: =COUNTA(J6:P6) -> 3
A7: 1 | B7: AURORA | C7: 5 | D7: Bagong Mandaue | E7: 7.9615, 123.5214 | F7: ✔️ | H7: Dipalutao BS | I7: 7.95464,123.4607 | J7: X | Q7: =IF(COUNTA(J7:P7)=0,FALSE,TRUE) -> TRUE | R7: =COUNTA(J7:P7) -> 1
A8: 1 | B8: AURORA | C8: 6 | D8: Bagong Maslog | E8: 7.9315, 123.5819 | F8: ✔️ | H8: San Jose BS | I8: 7.9556, 123.5828 | J8: X | Q8: =IF(COUNTA(J8:P8)=0,FALSE,TRUE) -> TRUE | R8: =COUNTA(J8:P8) -> 1
A9: 1 | B9: AURORA | C9: 7 | D9: Bagong Oslob | E9: 7.8863, 123.6434 | G9: ❌ | H9: San Jose BS | I9: 7.9556, 123.5828 | Q9: =IF(COUNTA(J9:P9)=0,FALSE,TRUE) -> FALSE | R9: =COUNTA(J9:P9) -> 0
A10: 1 | B10: AURORA | C10: 8 | D10: Bagong Pitogo | E10: 7.9298, 123.5752 | F10: ✔️ | H10: Dipalutao BS | I10: 7.95464,123.4607 | J10: X | Q10: =IF(COUNTA(J10:P10)=0,FALSE,TRUE) -> TRUE | R10: =COUNTA(J10:P10) -> 1
A11: 1 | B11: AURORA | C11: 9 | D11: Baki | E11: 7.9571, 123.53150 | F11: ✔️ | H11: Dipalutao BS | I11: 7.95464,123.4607 | J11: X | Q11: =IF(COUNTA(J11:P11)=0,FALSE,TRUE) -> TRUE | R11: =COUNTA(J11:P11) -> 1
A12: 1 | B12: AURORA | C12: 10 | D12: Balas | E12: 7.9776, 123.6345 | F12: ✔️ | H12: Bambong Daku | I12: 8.0328, 123.466 | Q12: =IF(COUNTA(J12:P12)=0,FALSE,TRUE) -> FALSE | R12: =COUNTA(J12:P12) -> 0
A13: 1 | B13: AURORA | C13: 11 | D13: Balide | E13: 7.9351, 123.5983 | F13: ✔️ | H13: San Jose BS | I13: 7.9556, 123.5828 | Q13: =IF(COUNTA(J13:P13)=0,FALSE,TRUE) -> FALSE | R13: =COUNTA(J13:P13) -> 0
A14: 1 | B14: AURORA | C14: 12 | D14: Balintawak | E14: 7.9572, 123.4962 | F14: ✔️ | H14: Dipalutao BS | I14: 7.95464,123.4607 | J14: X | Q14: =IF(COUNTA(J14:P14)=0,FALSE,TRUE) -> TRUE | R14: =COUNTA(J14:P14) -> 1
A15: 1 | B15: AURORA | C15: 13 | D15: Bayabas | E15: 7.9403, 123.6068 | F15: ✔️ | H15: San Jose BS | I15: 7.9556, 123.5828 | Q15: =IF(COUNTA(J15:P15)=0,FALSE,TRUE) -> FALSE | R15: =COUNTA(J15:P15) -> 0
A16: 1 | B16: AURORA | C16: 14 | D16: Bemposa | E16: 7.9348, 123.5527 | F16: ✔️ | H16: Dipalutao BS | I16: 7.95464,123.4607 | J16: X | Q16: =IF(COUNTA(J16:P16)=0,FALSE,TRUE) -> TRUE | R16: =COUNTA(J16:P16) -> 1
A17: 1 | B17: AURORA | C17: 15 | D17: Cabilinan | E17: 7.9306, 123.5886 | F17: ✔️ | H17: Dipalutao BS | I17: 7.95464,123.4607 | Q17: =IF(COUNTA(J17:P17)=0,FALSE,TRUE) -> FALSE | R17: =COUNTA(J17:P17) -> 0
A18: 1 | B18: AURORA | C18: 16 | D18: Campo Uno | E18: 7.9839, 123.5507 | F18: ✔️ | H18: Kapalaran BS | I18: 8.0309, 123.5401 | J18: X | Q18: =IF(COUNTA(J18:P18)=0,FALSE,TRUE) -> TRUE | R18: =COUNTA(J18:P18) -> 1
A19: 1 | B19: AURORA | C19: 17 | D19: Ceboneg | E19: 7.8902, 123.6579 | G19: ❌ | H19: San Jose BS | I19: 7.9556, 123.5828 | Q19: =IF(COUNTA(J19:P19)=0,FALSE,TRUE) -> FALSE | R19: =COUNTA(J19:P19) -> 0
A20: 1 | B20: AURORA | C20: 18 | D20: Commonwealth | E20: 7.9754, 123.5339 | F20: ✔️ | H20: Dipalutao BS | I20: 7.95464,123.4607 | J20: X | K20: X | Q20: =IF(COUNTA(J20:P20)=0,FALSE,TRUE) -> TRUE | R20: =COUNTA(J20:P20) -> 2
A21: 1 | B21: AURORA | C21: 19 | D21: Gubaan | E21: 7.9793, 123.5819 | G21: ❌ | H21: San Jose BS | I21: 7.9556, 123.5828 | Q21: =IF(COUNTA(J21:P21)=0,FALSE,TRUE) -> FALSE | R21: =COUNTA(J21:P21) -> 0
A22: 1 | B22: AURORA | C22: 20 | D22: Inasagan | E22: 7.9749, 123.5595 | F22: ✔️ | H22: Bogo Capalaran | I22: 8.1042, 123.4882 | Q22: =IF(COUNTA(J22:P22)=0,FALSE,TRUE) -> FALSE | R22: =COUNTA(J22:P22) -> 0
A23: 1 | B23: AURORA | C23: 21 | D23: Inroad | E23: 7.9103, 123.6454 | G23: ❌ | H23: San Jose BS | I23: 7.9556, 123.5828 | Q23: =IF(COUNTA(J23:P23)=0,FALSE,TRUE) -> FALSE | R23: =COUNTA(J23:P23) -> 0
A24: 1 | B24: AURORA | C24: 22 | D24: Kahayagan East | E24: 7.9814, 123.5190 | F24: ✔️ | H24: Dipalutao BS | I24: 7.95464,123.4607 | J24: X | Q24: =IF(COUNTA(J24:P24)=0,FALSE,TRUE) -> TRUE | R24: =COUNTA(J24:P24) -> 1
A25: 1 | B25: AURORA | C25: 23 | D25: Kahayagan West | E25: 7.9844, 123.5110 | F25: ✔️ | H25: Dipalutao BS | I25: 7.95464,123.4607 | J25: X | Q25: =IF(COUNTA(J25:P25)=0,FALSE,TRUE) -> TRUE | R25: =COUNTA(J25:P25) -> 1
A26: 1 | B26: AURORA | C26: 24 | D26: Kauswagan | E26: 8.0057, 123.5302 | F26: ✔️ | H26: Kapalaran BS | I26: 8.0309, 123.5401 | J26: X | L26: X | Q26: =IF(COUNTA(J26:P26)=0,FALSE,TRUE) -> TRUE | R26: =COUNTA(J26:P26) -> 2
A27: 1 | B27: AURORA | C27: 25 | D27: La Paz | E27: 7.9564, 123.5962 | G27: ❌ | H27: San Jose BS | I27: 7.9556, 123.5828 | Q27: =IF(COUNTA(J27:P27)=0,FALSE,TRUE) -> FALSE | R27: =COUNTA(J27:P27) -> 0
A28: 1 | B28: AURORA | C28: 26 | D28: La Victoria | E28: 7.9695, 123.5488 | F28: ✔️ | H28: Dipalutao BS | I28: 7.95464,123.4607 | J28: X | Q28: =IF(COUNTA(J28:P28)=0,FALSE,TRUE) -> TRUE | R28: =COUNTA(J28:P28) -> 1
A29: 1 | B29: AURORA | C29: 27 | D29: Lantungan | E29: 7.8986, 123.6308 | F29: ✔️ | H29: Dipalutao BS | I29: 7.95464,123.4607 | Q29: =IF(COUNTA(J29:P29)=0,FALSE,TRUE) -> FALSE | R29: =COUNTA(J29:P29) -> 0
A30: 1 | B30: AURORA | C30: 28 | D30: Libertad | E30: 7.9645, 123.5619 | F30: ✔️ | H30: Dipalutao BS | I30: 7.95464,123.4607 | J30: X | Q30: =IF(COUNTA(J30:P30)=0,FALSE,TRUE) -> TRUE | R30: =COUNTA(J30:P30) -> 1
A31: 1 | B31: AURORA | C31: 29 | D31: Lintugop | E31: 7.9519, 123.6179 | G31: ❌ | H31: San Jose BS | I31: 7.9556, 123.5828 | Q31: =IF(COUNTA(J31:P31)=0,FALSE,TRUE) -> FALSE | R31: =COUNTA(J31:P31) -> 0
A32: 1 | B32: AURORA | C32: 30 | D32: Lubid | E32: 7.9080, 123.6127 | F32: ✔️ | H32: Dipalutao BS | I32: 7.95464,123.4607 | Q32: =IF(COUNTA(J32:P32)=0,FALSE,TRUE) -> FALSE | R32: =COUNTA(J32:P32) -> 0
A33: 1 | B33: AURORA | C33: 31 | D33: Maguikay | E33: 7.9527, 123.5534 | F33: ✔️ | H33: Dipalutao BS | I33: 7.95464,123.4607 | Q33: =IF(COUNTA(J33:P33)=0,FALSE,TRUE) -> FALSE | R33: =COUNTA(J33:P33) -> 0
A34: 1 | B34: AURORA | C34: 32 | D34: Mahayahay | E34: 7.9671, 123.5845 | F34: ✔️ | H34: Kapalaran BS | I34: 8.0309, 123.5401 | J34: X | Q34: =IF(COUNTA(J34:P34)=0,FALSE,TRUE) -> TRUE | R34: =COUNTA(J34:P34) -> 1
A35: 1 | B35: AURORA | C35: 33 | D35: Monte Alegre | E35: 7.9889, 123.4986 | F35: ✔️ | H35: Dipalutao BS | I35: 7.95464,123.4607 | J35: X | L35: X | Q35: =IF(COUNTA(J35:P35)=0,FALSE,TRUE) -> TRUE | R35: =COUNTA(J35:P35) -> 2
A36: 1 | B36: AURORA | C36: 34 | D36: Montela | E36: 7.9726, 123.4914 | F36: ✔️ | H36: Dipalutao BS | I36: 7.95464,123.4607 | J36: X | K36: X | Q36: =IF(COUNTA(J36:P36)=0,FALSE,TRUE) -> TRUE | R36: =COUNTA(J36:P36) -> 2
A37: 1 | B37: AURORA | C37: 35 | D37: Napo | E37: 7.9174, 123.6496 | F37: ✔️ | H37: Dipalutao BS | I37: 7.95464,123.4607 | Q37: =IF(COUNTA(J37:P37)=0,FALSE,TRUE) -> FALSE | R37: =COUNTA(J37:P37) -> 0
A38: 1 | B38: AURORA | C38: 36 | D38: Panaghiusa | E38: 7.9621, 123.5315 | F38: ✔️ | H38: Dipalutao BS | I38: 7.95464,123.4607 | Q38: =IF(COUNTA(J38:P38)=0,FALSE,TRUE) -> FALSE | R38: =COUNTA(J38:P38) -> 0
A39: 1 | B39: AURORA | C39: 37 | D39: Poblacion | E39: 7.9486, 123.5842 | F39: ✔️ | H39: San Jose BS | I39: 7.9556, 123.5828 | J39: X | Q39: =IF(COUNTA(J39:P39)=0,FALSE,TRUE) -> TRUE | R39: =COUNTA(J39:P39) -> 1
A40: 1 | B40: AURORA | C40: 38 | D40: Resthouse | E40: 7.9019, 123.6516 | F40: ✔️ | H40: Dipalutao BS | I40: 7.95464,123.4607 | Q40: =IF(COUNTA(J40:P40)=0,FALSE,TRUE) -> FALSE | R40: =COUNTA(J40:P40) -> 0
...

Sheet LINE OF SIGHT
A1: MUNICIPALITY | C1: BARANGAYS | F1: LINK INFORMATION | J1: INSTALLATIONS
A2: NO | B2: MUN NAME | C2: NO | D2: BRGY NAME | E2: COORDINATES | F2: LOS | H2: BASE STATION | I2: COORDINATES | J2: BAP | K2: ELS | L2: NHS | M2: SHS | N2: REL | O2: ETC | P2: MRK
A3: 1 | B3: ARORA | C3: 1 | D3: Acad | E3: 7.9191, 123.6365 | F3: ✔️ | H3: Dipalutao BS | I3: 7.95464,123.4607 | J3: X | N3: X | P3: =IF(COUNTA(J3:O3)=0,FALSE,TRUE) -> TRUE
A4: 1 | B4: ARORA | C4: 2 | D4: Alang-Alang | E4: 7.9365, 123.5768 | F4: ✔️ | H4: San Jose BS | I4: 7.9556, 123.5828 | P4: =IF(COUNTA(J4:O4)=0,FALSE,TRUE) -> FALSE
A5: 1 | B5: ARORA | C5: 3 | D5: Alegria | E5: 7.9443, 123.5537 | F5: ✔️ | H5: Dipalutao BS | I5: 7.95464,123.4607 | J5: X | P5: =IF(COUNTA(J5:O5)=0,FALSE,TRUE) -> TRUE
A6: 1 | B6: ARORA | C6: 4 | D6: Anonang | E6: 7.9407, 123.6245 | F6: ✔️ | H6: Dipalutao BS | I6: 7.95464,123.4607 | J6: X | N6: X | P6: =IF(COUNTA(J6:O6)=0,FALSE,TRUE) -> TRUE
A7: 1 | B7: ARORA | C7: 5 | D7: Bagong Mandaue | E7: 7.9615, 123.5214 | F7: ✔️ | H7: Dipalutao BS | I7: 7.95464,123.4607 | J7: X | P7: =IF(COUNTA(J7:O7)=0,FALSE,TRUE) -> TRUE
A8: 1 | B8: ARORA | C8: 6 | D8: Bagong Maslog | E8: 7.9315, 123.5819 | F8: ✔️ | H8: San Jose BS | I8: 7.9556, 123.5828 | J8: X | P8: =IF(COUNTA(J8:O8)=0,FALSE,TRUE) -> TRUE
A9: 1 | B9: ARORA | C9: 7 | D9: Bagong Oslob | E9: 7.8863, 123.6434 | G9: ❌ | H9: San Jose BS | I9: 7.9556, 123.5828 | P9: =IF(COUNTA(J9:O9)=0,FALSE,TRUE) -> FALSE
A10: 1 | B10: ARORA | C10: 8 | D10: Bagong Pitogo | E10: 7.9298, 123.5752 | F10: ✔️ | H10: Dipalutao BS | I10: 7.95464,123.4607 | J10: X | P10: =IF(COUNTA(J10:O10)=0,FALSE,TRUE) -> TRUE
A11: 1 | B11: ARORA | C11: 9 | D11: Baki | E11: 7.9571, 123.53150 | F11: ✔️ | H11: Dipalutao BS | I11: 7.95464,123.4607 | J11: X | P11: =IF(COUNTA(J11:O11)=0,FALSE,TRUE) -> TRUE
A12: 1 | B12: ARORA | C12: 10 | D12: Balas | E12: 7.9776, 123.6345 | F12: ✔️ | H12: Bambong Daku | I12: 8.0328, 123.466 | P12: =IF(COUNTA(J12:O12)=0,FALSE,TRUE) -> FALSE
A13: 1 | B13: ARORA | C13: 11 | D13: Balide | E13: 7.9351, 123.5983 | F13: ✔️ | H13: San Jose BS | I13: 7.9556, 123.5828 | P13: =IF(COUNTA(J13:O13)=0,FALSE,TRUE) -> FALSE
A14: 1 | B14: ARORA | C14: 12 | D14: Balintawak | E14: 7.9572, 123.4962 | F14: ✔️ | H14: Dipalutao BS | I14: 7.95464,123.4607 | J14: X | P14: =IF(COUNTA(J14:O14)=0,FALSE,TRUE) -> TRUE
A15: 1 | B15: ARORA | C15: 13 | D15: Bayabas | E15: 7.9403, 123.6068 | F15: ✔️ | H15: San Jose BS | I15: 7.9556, 123.5828 | P15: =IF(COUNTA(J15:O15)=0,FALSE,TRUE) -> FALSE
A16: 1 | B16: ARORA | C16: 14 | D16: Bemposa | E16: 7.9348, 123.5527 | F16: ✔️ | H16: Dipalutao BS | I16: 7.95464,123.4607 | J16: X | P16: =IF(COUNTA(J16:O16)=0,FALSE,TRUE) -> TRUE
A17: 1 | B17: ARORA | C17: 15 | D17: Cabilinan | E17: 7.9306, 123.5886 | F17: ✔️ | H17: Dipalutao BS | I17: 7.95464,123.4607 | P17: =IF(COUNTA(J17:O17)=0,FALSE,TRUE) -> FALSE
A18: 1 | B18: ARORA | C18: 16 | D18: Campo Uno | E18: 7.9839, 123.5507 | F18: ✔️ | H18: Kapalaran BS | I18: 8.0309, 123.5401 | J18: X | P18: =IF(COUNTA(J18:O18)=0,FALSE,TRUE) -> TRUE
A19: 1 | B19: ARORA | C19: 17 | D19: Ceboneg | E19: 7.8902, 123.6579 | G19: ❌ | H19: San Jose BS | I19: 7.9556, 123.5828 | P19: =IF(COUNTA(J19:O19)=0,FALSE,TRUE) -> FALSE
A20: 1 | B20: ARORA | C20: 18 | D20: Commonwealth | E20: 7.9754, 123.5339 | F20: ✔️ | H20: Dipalutao BS | I20: 7.95464,123.4607 | J20: X | K20: X | P20: =IF(COUNTA(J20:O20)=0,FALSE,TRUE) -> TRUE
A21: 1 | B21: ARORA | C21: 19 | D21: Gubaan | E21: 7.9793, 123.5819 | G21: ❌ | H21: San Jose BS | I21: 7.9556, 123.5828 | P21: =IF(COUNTA(J21:O21)=0,FALSE,TRUE) -> FALSE
A22: 1 | B22: ARORA | C22: 20 | D22: Inasagan | E22: 7.9749, 123.5595 | F22: ✔️ | H22: Bogo Capalaran | I22: 8.1042, 123.4882 | P22: =IF(COUNTA(J22:O22)=0,FALSE,TRUE) -> FALSE
A23: 1 | B23: ARORA | C23: 21 | D23: Inroad | E23: 7.9103, 123.6454 | G23: ❌ | H23: San Jose BS | I23: 7.9556, 123.5828 | P23: =IF(COUNTA(J23:O23)=0,FALSE,TRUE) -> FALSE
A24: 1 | B24: ARORA | C24: 22 | D24: Kahayagan East | E24: 7.9814, 123.5190 | F24: ✔️ | H24: Dipalutao BS | I24: 7.95464,123.4607 | J24: X | P24: =IF(COUNTA(J24:O24)=0,FALSE,TRUE) -> TRUE
A25: 1 | B25: ARORA | C25: 23 | D25: Kahayagan West | E25: 7.9844, 123.5110 | F25: ✔️ | H25: Dipalutao BS | I25: 7.95464,123.4607 | J25: X | P25: =IF(COUNTA(J25:O25)=0,FALSE,TRUE) -> TRUE
A26: 1 | B26: ARORA | C26: 24 | D26: Kauswagan | E26: 8.0057, 123.5302 | F26: ✔️ | H26: Kapalaran BS | I26: 8.0309, 123.5401 | J26: X | L26: X | P26: =IF(COUNTA(J26:O26)=0,FALSE,TRUE) -> TRUE
A27: 1 | B27: ARORA | C27: 25 | D27: La Paz | E27: 7.9564, 123.5962 | G27: ❌ | H27: San Jose BS | I27: 7.9556, 123.5828 | P27: =IF(COUNTA(J27:O27)=0,FALSE,TRUE) -> FALSE
A28: 1 | B28: ARORA | C28: 26 | D28: La Victoria | E28: 7.9695, 123.5488 | F28: ✔️ | H28: Dipalutao BS | I28: 7.95464,123.4607 | J28: X | P28: =IF(COUNTA(J28:O28)=0,FALSE,TRUE) -> TRUE
A29: 1 | B29: ARORA | C29: 27 | D29: Lantungan | E29: 7.8986, 123.6308 | F29: ✔️ | H29: Dipalutao BS | I29: 7.95464,123.4607 | P29: =IF(COUNTA(J29:O29)=0,FALSE,TRUE) -> FALSE
A30: 1 | B30: ARORA | C30: 28 | D30: Libertad | E30: 7.9645, 123.5619 | F30: ✔️ | H30: Dipalutao BS | I30: 7.95464,123.4607 | J30: X | P30: =IF(COUNTA(J30:O30)=0,FALSE,TRUE) -> TRUE
A31: 1 | B31: ARORA | C31: 29 | D31: Lintugop | E31: 7.9519, 123.6179 | G31: ❌ | H31: San Jose BS | I31: 7.9556, 123.5828 | P31: =IF(COUNTA(J31:O31)=0,FALSE,TRUE) -> FALSE
A32: 1 | B32: ARORA | C32: 30 | D32: Lubid | E32: 7.9080, 123.6127 | F32: ✔️ | H32: Dipalutao BS | I32: 7.95464,123.4607 | P32: =IF(COUNTA(J32:O32)=0,FALSE,TRUE) -> FALSE
A33: 1 | B33: ARORA | C33: 31 | D33: Maguikay | E33: 7.9527, 123.5534 | F33: ✔️ | H33: Dipalutao BS | I33: 7.95464,123.4607 | P33: =IF(COUNTA(J33:O33)=0,FALSE,TRUE) -> FALSE
A34: 1 | B34: ARORA | C34: 32 | D34: Mahayahay | E34: 7.9671, 123.5845 | F34: ✔️ | H34: Kapalaran BS | I34: 8.0309, 123.5401 | J34: X | P34: =IF(COUNTA(J34:O34)=0,FALSE,TRUE) -> TRUE
A35: 1 | B35: ARORA | C35: 33 | D35: Monte Alegre | E35: 7.9889, 123.4986 | F35: ✔️ | H35: Dipalutao BS | I35: 7.95464,123.4607 | J35: X | L35: X | P35: =IF(COUNTA(J35:O35)=0,FALSE,TRUE) -> TRUE
A36: 1 | B36: ARORA | C36: 34 | D36: Montela | E36: 7.9726, 123.4914 | F36: ✔️ | H36: Dipalutao BS | I36: 7.95464,123.4607 | J36: X | K36: X | P36: =IF(COUNTA(J36:O36)=0,FALSE,TRUE) -> TRUE
A37: 1 | B37: ARORA | C37: 35 | D37: Napo | E37: 7.9174, 123.6496 | F37: ✔️ | H37: Dipalutao BS | I37: 7.95464,123.4607 | P37: =IF(COUNTA(J37:O37)=0,FALSE,TRUE) -> FALSE
A38: 1 | B38: ARORA | C38: 36 | D38: Panaghiusa | E38: 7.9621, 123.5315 | F38: ✔️ | H38: Dipalutao BS | I38: 7.95464,123.4607 | P38: =IF(COUNTA(J38:O38)=0,FALSE,TRUE) -> FALSE
A39: 1 | B39: ARORA | C39: 37 | D39: Poblacion | E39: 7.9486, 123.5842 | F39: ✔️ | H39: San Jose BS | I39: 7.9556, 123.5828 | J39: X | P39: =IF(COUNTA(J39:O39)=0,FALSE,TRUE) -> TRUE
A40: 1 | B40: ARORA | C40: 38 | D40: Resthouse | E40: 7.9019, 123.6516 | F40: ✔️ | H40: Dipalutao BS | I40: 7.95464,123.4607 | P40: =IF(COUNTA(J40:O40)=0,FALSE,TRUE) -> FALSE
...
